<?xml version="1.0" ?>
<!-- =================================================================================== -->
<!-- |    This document was autogenerated by xacro from /data/teleop/XRoboToolkit-Teleop-Sample-Python/franka_description/robots/fr3v2/fr3v2.urdf.xacro | -->
<!-- |    EDITING THIS FILE BY HAND IS NOT RECOMMENDED                                 | -->
<!-- =================================================================================== -->
<robot name="fr3v2">
  <!-- safety_distance: Minimum safety distance in [m] by which the collision volumes are expanded and which is enforced during robot motions -->
  <!-- robot_type: the franka robot arm type -->
  <!-- joint_limits: description of the joint limits that comes from a YAML file. Example definition: ${xacro.load_yaml('$(find franka_description)/robots/fr3/joint_limits.yaml')} -->
  <!-- kinematics: description of the kinematics that comes from a YAML file. Example definition: ${xacro.load_yaml('$(find franka_description)/robots/fr3/kinematics.yaml')} -->
  <!-- inertials: description of the inertials that comes from a YAML file. Example definition: ${xacro.load_yaml('$(find franka_description)/robots/fr3/inertials.yaml')} -->
  <!-- dynamics: description of the dynamics that comes from a YAML file. Example definition: ${xacro.load_yaml('$(find franka_description)/robots/fr3/dynamics.yaml')} -->
  <link name="base">
      </link>
  <joint name="fr3v2_base_joint" type="fixed">
    <parent link="base"/>
    <child link="fr3v2_link0"/>
    <origin rpy="0 0 0" xyz="0 0 0"/>
  </joint>
  <!-- sub-link defining detailed meshes for collision with environment -->
  <link name="fr3v2_link0">
    <visual name="fr3v2_link0_visual">
      <geometry>
        <mesh filename="assets/link0.obj"/>
      </geometry>
    </visual>
    <collision name="fr3v2_link0_collision">
      <geometry>
        <mesh filename="assets/link0.stl"/>
      </geometry>
    </collision>
    <inertial>
      <origin rpy="0 0 0" xyz="-0.017200 0.000400 0.074500"/>
      <mass value="2.3966"/>
      <inertia ixx="0.009" ixy="0.0" ixz="0.002" iyy="0.0115" iyz="0.0" izz="0.0085"/>
    </inertial>
  </link>
  <link name="fr3v2_link0_accelerometer_top">
      </link>
  <joint name="fr3v2_link0_accelerometer_top_joint" type="fixed">
    <origin rpy="3.1416 0.0 0.0" xyz="-0.017402 -0.007872 0.04715"/>
    <parent link="fr3v2_link0"/>
    <child link="fr3v2_link0_accelerometer_top"/>
  </joint>
  <link name="fr3v2_link0_accelerometer_bottom">
      </link>
  <joint name="fr3v2_link0_accelerometer_bottom_joint" type="fixed">
    <origin rpy="0.0 0.0 -1.5708" xyz="-0.019739 0.0015506 0.05075"/>
    <parent link="fr3v2_link0"/>
    <child link="fr3v2_link0_accelerometer_bottom"/>
  </joint>
  <!-- sub-link defining detailed meshes for collision with environment -->
  <link name="fr3v2_link1">
    <visual name="fr3v2_link1_visual">
      <geometry>
        <mesh filename="assets/link1.obj"/>
      </geometry>
    </visual>
    <collision name="fr3v2_link1_collision">
      <geometry>
        <mesh filename="assets/link1.stl"/>
      </geometry>
    </collision>
    <inertial>
      <origin rpy="0 0 0" xyz="-0.004580 0.027016 -0.061800"/>
      <mass value="2.4377"/>
      <inertia ixx="0.02324" ixy="0.000333" ixz="-0.000676" iyy="0.02146" iyz="0.003739" izz="0.0055"/>
    </inertial>
  </link>
  <link name="fr3v2_link1_accelerometer_top">
      </link>
  <joint name="fr3v2_link1_accelerometer_top_joint" type="fixed">
    <origin rpy="-1.5708 0.0 3.1416" xyz="0.017402 -0.093352 -0.00787"/>
    <parent link="fr3v2_link1"/>
    <child link="fr3v2_link1_accelerometer_top"/>
  </joint>
  <link name="fr3v2_link1_accelerometer_bottom">
      </link>
  <joint name="fr3v2_link1_accelerometer_bottom_joint" type="fixed">
    <origin rpy="-1.5708 1.5708 0.0" xyz="0.01974 -0.08975 0.00155"/>
    <parent link="fr3v2_link1"/>
    <child link="fr3v2_link1_accelerometer_bottom"/>
  </joint>
  <joint name="fr3v2_joint1" type="revolute">
    <origin rpy="0 0 0" xyz="0 0 0.333"/>
    <parent link="fr3v2_link0"/>
    <child link="fr3v2_link1"/>
    <axis xyz="0 0 1"/>
    <limit effort="87.0" lower="-2.9007400166666666" upper="2.9007400166666666" velocity="2.62"/>
    <safety_controller k_position="100.0" k_velocity="40.0" soft_lower_limit="-2.9007400166666666" soft_upper_limit="2.9007400166666666"/>
    <position_based_velocity_limits deceleration_limit="6.0" velocity_offset="0.6520000381679385"/>
    <dynamics D="1" K="7000" damping="0.003" friction="0.2" gear_ratio="120.0" motor_inertia="4.206399e-05" mu_coulomb="0" mu_viscous="16"/>
  </joint>
  <!-- sub-link defining detailed meshes for collision with environment -->
  <link name="fr3v2_link2">
    <visual name="fr3v2_link2_visual">
      <geometry>
        <mesh filename="assets/link2.obj"/>
      </geometry>
    </visual>
    <collision name="fr3v2_link2_collision">
      <geometry>
        <mesh filename="assets/link2.stl"/>
      </geometry>
    </collision>
    <inertial>
      <origin rpy="0 0 0" xyz="0.004541 -0.180691 -0.010479"/>
      <mass value="2.2375"/>
      <inertia ixx="0.019026" ixy="0.001241" ixz="0.000499" iyy="0.00566" iyz="-0.001804" izz="0.017114"/>
    </inertial>
  </link>
  <link name="fr3v2_link2_accelerometer_top">
      </link>
  <joint name="fr3v2_link2_accelerometer_top_joint" type="fixed">
    <origin rpy="1.5708 0.0 3.1416" xyz="0.017403 -0.11515 0.00787"/>
    <parent link="fr3v2_link2"/>
    <child link="fr3v2_link2_accelerometer_top"/>
  </joint>
  <link name="fr3v2_link2_accelerometer_bottom">
      </link>
  <joint name="fr3v2_link2_accelerometer_bottom_joint" type="fixed">
    <origin rpy="1.5708 -1.5708 0.0" xyz="0.019737 -0.11875 -0.00155"/>
    <parent link="fr3v2_link2"/>
    <child link="fr3v2_link2_accelerometer_bottom"/>
  </joint>
  <joint name="fr3v2_joint2" type="revolute">
    <origin rpy="-1.570796326794897 0 0" xyz="0 0 0"/>
    <parent link="fr3v2_link1"/>
    <child link="fr3v2_link2"/>
    <axis xyz="0 0 1"/>
    <limit effort="87.0" lower="-1.8360900166666667" upper="1.8360900166666667" velocity="2.62"/>
    <safety_controller k_position="100.0" k_velocity="40.0" soft_lower_limit="-1.8360900166666667" soft_upper_limit="1.8360900166666667"/>
    <position_based_velocity_limits deceleration_limit="2.585" velocity_offset="0.2499685851463105"/>
    <dynamics D="1" K="7000" damping="0.003" friction="0.2" gear_ratio="120.0" motor_inertia="4.206399e-05" mu_coulomb="0" mu_viscous="16"/>
  </joint>
  <!-- sub-link defining detailed meshes for collision with environment -->
  <link name="fr3v2_link3">
    <visual name="fr3v2_link3_visual">
      <geometry>
        <mesh filename="assets/link3.obj"/>
      </geometry>
    </visual>
    <collision name="fr3v2_link3_collision">
      <geometry>
        <mesh filename="assets/link3.stl"/>
      </geometry>
    </collision>
    <inertial>
      <origin rpy="0 0 0" xyz="0.082540 0.019082 0.042027"/>
      <mass value="2.193082"/>
      <inertia ixx="0.010225" ixy="0.001144" ixz="0.003497" iyy="0.012398" iyz="0.002156" izz="0.006877"/>
    </inertial>
  </link>
  <link name="fr3v2_link3_accelerometer_top">
      </link>
  <joint name="fr3v2_link3_accelerometer_top_joint" type="fixed">
    <origin rpy="-1.5708 0.0 0.0" xyz="0.065099 0.077352 -0.00787"/>
    <parent link="fr3v2_link3"/>
    <child link="fr3v2_link3_accelerometer_top"/>
  </joint>
  <link name="fr3v2_link3_accelerometer_bottom">
      </link>
  <joint name="fr3v2_link3_accelerometer_bottom_joint" type="fixed">
    <origin rpy="1.5708 1.5708 0.0" xyz="0.062769 0.073756 0.00155"/>
    <parent link="fr3v2_link3"/>
    <child link="fr3v2_link3_accelerometer_bottom"/>
  </joint>
  <joint name="fr3v2_joint3" type="revolute">
    <origin rpy="1.570796326794897 0 0" xyz="0 -0.316 0"/>
    <parent link="fr3v2_link2"/>
    <child link="fr3v2_link3"/>
    <axis xyz="0 0 1"/>
    <limit effort="87.0" lower="-2.9007400166666666" upper="2.9007400166666666" velocity="2.62"/>
    <safety_controller k_position="100.0" k_velocity="40.0" soft_lower_limit="-2.9007400166666666" soft_upper_limit="2.9007400166666666"/>
    <position_based_velocity_limits deceleration_limit="3.5" velocity_offset="0.20053055661577582"/>
    <dynamics D="1" K="7000" damping="0.003" friction="0.2" gear_ratio="120.0" motor_inertia="3.211626e-05" mu_coulomb="0" mu_viscous="16"/>
  </joint>
  <!-- sub-link defining detailed meshes for collision with environment -->
  <link name="fr3v2_link4">
    <visual name="fr3v2_link4_visual">
      <geometry>
        <mesh filename="assets/link4.obj"/>
      </geometry>
    </visual>
    <collision name="fr3v2_link4_collision">
      <geometry>
        <mesh filename="assets/link4.stl"/>
      </geometry>
    </collision>
    <inertial>
      <origin rpy="0 0 0" xyz="-0.087533 0.096335 0.010120"/>
      <mass value="2.181537"/>
      <inertia ixx="0.008878" ixy="-0.003749" ixz="0.001139" iyy="0.007628" iyz="-0.00046" izz="0.010295"/>
    </inertial>
  </link>
  <link name="fr3v2_link4_accelerometer_top">
      </link>
  <joint name="fr3v2_link4_accelerometer_top_joint" type="fixed">
    <origin rpy="-1.5708 0.0 -3.1416" xyz="-0.0651 0.046152 -0.00787"/>
    <parent link="fr3v2_link4"/>
    <child link="fr3v2_link4_accelerometer_top"/>
  </joint>
  <link name="fr3v2_link4_accelerometer_bottom">
      </link>
  <joint name="fr3v2_link4_accelerometer_bottom_joint" type="fixed">
    <origin rpy="-1.5708 1.5708 0.0" xyz="-0.062775 0.049753 0.00155"/>
    <parent link="fr3v2_link4"/>
    <child link="fr3v2_link4_accelerometer_bottom"/>
  </joint>
  <joint name="fr3v2_joint4" type="revolute">
    <origin rpy="1.570796326794897 0 0" xyz="0.0825 0 0"/>
    <parent link="fr3v2_link3"/>
    <child link="fr3v2_link4"/>
    <axis xyz="0 0 1"/>
    <limit effort="87.0" lower="-3.077020016666667" upper="-0.11693708333333333" velocity="2.62"/>
    <safety_controller k_position="100.0" k_velocity="40.0" soft_lower_limit="-3.077020016666667" soft_upper_limit="-0.11693708333333333"/>
    <position_based_velocity_limits deceleration_limit="4.0" velocity_offset="0.3542181933842238"/>
    <dynamics D="1" K="7000" damping="0.003" friction="0.2" gear_ratio="120.0" motor_inertia="3.211626e-05" mu_coulomb="0" mu_viscous="16"/>
  </joint>
  <!-- sub-link defining detailed meshes for collision with environment -->
  <link name="fr3v2_link5">
    <visual name="fr3v2_link5_visual">
      <geometry>
        <mesh filename="assets/link5.obj"/>
      </geometry>
    </visual>
    <collision name="fr3v2_link5_collision">
      <geometry>
        <mesh filename="assets/link5.stl"/>
      </geometry>
    </collision>
    <inertial>
      <origin rpy="0 0 0" xyz="0.008383 0.010180 -0.053265"/>
      <mass value="2.186881"/>
      <inertia ixx="0.031874" ixy="0.000134" ixz="-0.000265" iyy="0.029674" iyz="-0.004734" izz="0.004751"/>
    </inertial>
  </link>
  <link name="fr3v2_link5_accelerometer_top">
      </link>
  <joint name="fr3v2_link5_accelerometer_top_joint" type="fixed">
    <origin rpy="-1.5708 0.0 0.0" xyz="-0.017363 0.085872 -0.00795"/>
    <parent link="fr3v2_link5"/>
    <child link="fr3v2_link5_accelerometer_top"/>
  </joint>
  <link name="fr3v2_link5_accelerometer_bottom">
      </link>
  <joint name="fr3v2_link5_accelerometer_bottom_joint" type="fixed">
    <origin rpy="1.5708 1.5708 0.0" xyz="-0.019742 0.082275 0.00146"/>
    <parent link="fr3v2_link5"/>
    <child link="fr3v2_link5_accelerometer_bottom"/>
  </joint>
  <joint name="fr3v2_joint5" type="revolute">
    <origin rpy="-1.570796326794897 0 0" xyz="-0.0825 0.384 0"/>
    <parent link="fr3v2_link4"/>
    <child link="fr3v2_link5"/>
    <axis xyz="0 0 1"/>
    <limit effort="12.0" lower="-2.87630335" upper="2.87630335" velocity="5.26"/>
    <safety_controller k_position="100.0" k_velocity="40.0" soft_lower_limit="-2.87630335" soft_upper_limit="2.87630335"/>
    <position_based_velocity_limits deceleration_limit="17.0" velocity_offset="0.5738321197718637"/>
    <dynamics D="1" K="7000" damping="0.003" friction="0.2" gear_ratio="80.0" motor_inertia="3.211626e-05" mu_coulomb="0" mu_viscous="16"/>
  </joint>
  <!-- sub-link defining detailed meshes for collision with environment -->
  <link name="fr3v2_link6">
    <visual name="fr3v2_link6_visual">
      <geometry>
        <mesh filename="assets/link6.obj"/>
      </geometry>
    </visual>
    <collision name="fr3v2_link6_collision">
      <geometry>
        <mesh filename="assets/link6.stl"/>
      </geometry>
    </collision>
    <inertial>
      <origin rpy="0 0 0" xyz="0.070391 -0.016074 -0.035025"/>
      <mass value="1.579681"/>
      <inertia ixx="0.00286" ixy="-0.000553" ixz="-0.000638" iyy="0.00391" iyz="-0.00024" izz="0.00453"/>
    </inertial>
  </link>
  <joint name="fr3v2_joint6" type="revolute">
    <origin rpy="1.570796326794897 0 0" xyz="0 0 0"/>
    <parent link="fr3v2_link5"/>
    <child link="fr3v2_link6"/>
    <axis xyz="0 0 1"/>
    <limit effort="12.0" lower="0.43982265" upper="4.62163335" velocity="4.18"/>
    <safety_controller k_position="100.0" k_velocity="40.0" soft_lower_limit="0.43982265" soft_upper_limit="4.62163335"/>
    <position_based_velocity_limits deceleration_limit="5.5" velocity_offset="0.4884649342105264"/>
    <dynamics D="1" K="7000" damping="0.003" friction="0.2" gear_ratio="80.0" motor_inertia="3.211626e-05" mu_coulomb="0" mu_viscous="16"/>
  </joint>
  <!-- sub-link defining detailed meshes for collision with environment -->
  <link name="fr3v2_link7">
    <visual name="fr3v2_link7_visual">
      <geometry>
        <mesh filename="assets/link7.obj"/>
      </geometry>
    </visual>
    <collision name="fr3v2_link7_collision">
      <geometry>
        <mesh filename="assets/link7.stl"/>
      </geometry>
    </collision>
    <inertial>
      <origin rpy="0 0 0" xyz="-0.009108 0.018151 0.064946"/>
      <mass value="0.694841"/>
      <inertia ixx="0.000899" ixy="0.0" ixz="-1.3e-05" iyy="0.001099" iyz="-2.2e-05" izz="0.000702"/>
    </inertial>
  </link>
  <joint name="fr3v2_joint7" type="revolute">
    <origin rpy="1.570796326794897 0 0" xyz="0.088 0 0"/>
    <parent link="fr3v2_link6"/>
    <child link="fr3v2_link7"/>
    <axis xyz="0 0 1"/>
    <limit effort="12.0" lower="-3.05083335" upper="3.05083335" velocity="5.26"/>
    <safety_controller k_position="100.0" k_velocity="40.0" soft_lower_limit="-3.05083335" soft_upper_limit="3.05083335"/>
    <position_based_velocity_limits deceleration_limit="17.0" velocity_offset="0.4591952376425851"/>
    <dynamics D="1" K="7000" damping="0.003" friction="0.2" gear_ratio="80.0" motor_inertia="3.211626e-05" mu_coulomb="0" mu_viscous="16"/>
  </joint>
  <link name="fr3v2_link8"/>
  <joint name="fr3v2_joint8" type="fixed">
    <origin rpy="0 0 0" xyz="0 0 0.107"/>
    <parent link="fr3v2_link7"/>
    <child link="fr3v2_link8"/>
  </joint>
  <joint name="fr3v2_hand_joint" type="fixed">
    <parent link="fr3v2_link8"/>
    <child link="fr3v2_hand"/>
    <origin rpy="0 0 -0.7853981633974483" xyz="0 0 0"/>
  </joint>
  <!-- sub-link defining detailed meshes for collision with environment -->
  <link name="fr3v2_hand">
    <visual name="fr3v2_hand_visual">
      <geometry>
        <mesh filename="assets/hand.stl"/>
      </geometry>
    </visual>
    <collision name="fr3v2_hand_collision">
      <geometry>
        <mesh filename="assets/hand.stl"/>
      </geometry>
    </collision>
    <inertial>
      <origin rpy="0 0 0" xyz="-0.0000376 0.0119128 0.0207260"/>
      <mass value="0.6544"/>
      <inertia ixx="0.00186" ixy="0.0" ixz="0.0" iyy="0.0003" iyz="-2e-05" izz="0.00174"/>
    </inertial>
  </link>
  <!-- Define the hand_tcp frame -->
  <link name="fr3v2_hand_tcp"/>
  <joint name="fr3v2_hand_tcp_joint" type="fixed">
    <origin rpy="0 0 0" xyz="0 0 0.1034"/>
    <parent link="fr3v2_hand"/>
    <child link="fr3v2_hand_tcp"/>
  </joint>
  <link name="fr3v2_leftfinger">
    <visual name="fr3v2_leftfinger_visual">
      <geometry>
        <mesh filename="assets/finger_0.obj"/>
      </geometry>
    </visual>
    <!-- screw mount -->
    <collision>
      <origin rpy="0 0 0" xyz="0 18.5e-3 11e-3"/>
      <geometry>
        <box size="22e-3 15e-3 20e-3"/>
      </geometry>
    </collision>
    <!-- cartriage sledge -->
    <collision>
      <origin rpy="0 0 0" xyz="0 6.8e-3 2.2e-3"/>
      <geometry>
        <box size="22e-3 8.8e-3 3.8e-3"/>
      </geometry>
    </collision>
    <!-- diagonal finger -->
    <collision>
      <origin rpy="0.5235987755982988 0 0" xyz="0 15.9e-3 28.35e-3"/>
      <geometry>
        <box size="17.5e-3 7e-3 23.5e-3"/>
      </geometry>
    </collision>
    <!-- rubber tip with which to grasp -->
    <collision>
      <origin rpy="0 0 0" xyz="0 7.58e-3 45.25e-3"/>
      <geometry>
        <box size="17.5e-3 15.2e-3 18.5e-3"/>
      </geometry>
    </collision>
    <inertial>
      <origin rpy="0 0 0" xyz="0 0.0152850 0.0219675"/>
      <mass value="0.0291"/>
      <inertia ixx="8.49e-06" ixy="0.0" ixz="0.0" iyy="8.53e-06" iyz="-1.06e-06" izz="1.77e-06"/>
    </inertial>
  </link>
  <link name="fr3v2_rightfinger">
    <visual name="fr3v2_rightfinger_visual">
      <origin rpy="0 0 0" xyz="0 0 0"/>
      <geometry>
        <mesh filename="assets/finger_0.obj"/>
      </geometry>
    </visual>
    <!-- screw mount -->
    <collision>
      <origin rpy="0 0 0" xyz="0 18.5e-3 11e-3"/>
      <geometry>
        <box size="22e-3 15e-3 20e-3"/>
      </geometry>
    </collision>
    <!-- cartriage sledge -->
    <collision>
      <origin rpy="0 0 0" xyz="0 6.8e-3 2.2e-3"/>
      <geometry>
        <box size="22e-3 8.8e-3 3.8e-3"/>
      </geometry>
    </collision>
    <!-- diagonal finger -->
    <collision>
      <origin rpy="-0.5235987755982988 0 3.141592653589793" xyz="0 15.9e-3 28.35e-3"/>
      <geometry>
        <box size="17.5e-3 7e-3 23.5e-3"/>
      </geometry>
    </collision>
    <!-- rubber tip with which to grasp -->
    <collision>
      <origin rpy="0 0 0" xyz="0 7.58e-3 45.25e-3"/>
      <geometry>
        <box size="17.5e-3 15.2e-3 18.5e-3"/>
      </geometry>
    </collision>
    <inertial>
      <origin rpy="0 0 0" xyz="0 0.0152850 0.0219675"/>
      <mass value="0.0291"/>
      <inertia ixx="8.49e-06" ixy="0.0" ixz="0.0" iyy="8.53e-06" iyz="-1.06e-06" izz="1.77e-06"/>
    </inertial>
  </link>
  <joint name="fr3v2_finger_joint1" type="prismatic">
    <parent link="fr3v2_hand"/>
    <child link="fr3v2_leftfinger"/>
    <origin rpy="0 0 0" xyz="0 0 0.0584"/>
    <axis xyz="0 1 0"/>
    <limit effort="100" lower="0.0" upper="0.04" velocity="0.2"/>
    <dynamics damping="0.3"/>
  </joint>
  <joint name="fr3v2_finger_joint2" type="prismatic">
    <parent link="fr3v2_hand"/>
    <child link="fr3v2_rightfinger"/>
    <origin rpy="0 0 3.141592653589793" xyz="0 0 0.0584"/>
    <axis xyz="0 1 0"/>
    <limit effort="100" lower="0.0" upper="0.04" velocity="0.2"/>
    <mimic joint="fr3v2_finger_joint1"/>
    <dynamics damping="0.3"/>
  </joint>
</robot>
